<robot name="rover">
    <link name="base_footprint" />
    <link name="base_link">
        <visual name="">
            <origin xyz="0.0 0.0 0.0" rpy="0.0 0.0 0.0"/>
            <geometry>
                <box size="0.6 1.0 0.2"/>
            </geometry>
            <material name="red">
                <color rgba="1.0 0.0 0.0 1.0"/>
                <texture filename=""/>
            </material>
        </visual>
   </link>

    <joint name="base_joint" type="fixed">
        <origin xyz="0.0 0.0 0.2" rpy="0.0 0.0 0.0"/>
        <parent link="base_footprint"/>
        <child link="base_link"/>
        <axis xyz="0.0 0.0 0.0"/>
    </joint>

    <!-- Rear right wheel. -->
    <link name="wheel_rear_right_link">
        <visual name="">
    <!--            <origin xyz="0.35 0.35 0.0" rpy="${pi/2} 0.0 ${pi/2}"/> -->
            <origin xyz="0.0 0.0 0.0" rpy="0.0 0.0 0.0"/>
                <geometry>
                    <cylinder radius="0.15" length="0.1"/>
                </geometry>
                <material name="yellow">
                    <color rgba="1.0 1.0 0.0 1.0"/>
                    <texture filename=""/>
                </material>
        </visual>
        <collision>
            <origin xyz="0.0 0.0 0.0" rpy="0.0 0.0 0.0"/>
            <geometry>
                <cylinder radius="0.15" length="0.1"/>
            </geometry>
        </collision>
    </link>

    <joint name="wheel_rear_right_joint" type="continuous">
        <origin xyz="0.35 0.35 0.0" rpy="1.57 0.0 1.57"/>
        <parent link="base_link"/>
        <child link="wheel_rear_right_link"/>
        <axis xyz="0.0 0.0 1.0"/>
    </joint>


    <!-- Rear left wheel. -->
    <link name="wheel_rear_left_link">
        <visual name="">
    <!--            <origin xyz="0.35 0.35 0.0" rpy="${pi/2} 0.0 ${pi/2}"/> -->
            <origin xyz="0.0 0.0 0.0" rpy="0.0 0.0 0.0"/>
                <geometry>
                    <cylinder radius="0.15" length="0.1"/>
                </geometry>
                <material name="green">
                    <color rgba="0.0 1.0 0.0 1.0"/>
                    <texture filename=""/>
                </material>
        </visual>
        <collision>
            <origin xyz="0.0 0.0 0.0" rpy="0.0 0.0 0.0"/>
            <geometry>
                <cylinder radius="0.15" length="0.1"/>
            </geometry>
        </collision>
    </link>

    <joint name="wheel_rear_left_joint" type="continuous">
        <origin xyz="-0.35 0.35 0.0" rpy="1.57 0.0 1.57"/>
        <parent link="base_link"/>
        <child link="wheel_rear_left_link"/>
        <axis xyz="0.0 0.0 1.0"/>
    </joint>

</robot>
