<?xml version="1.0"?>
<robot xmlns:xacro="http://www.ros.org/wiki/xacro" name="rover">
    
    <link name="base_footprint" />

    <xacro:property name="left_wheel" value="package://mobile_robot/meshes/left_tire.stl"/>
    <xacro:property name="right_wheel" value="package://mobile_robot/meshes/right_tire.stl"/>
    <xacro:property name="constant" value="${1/12}"/>
    <xacro:property name="mass"   value="1.0"/>
    <xacro:property name="width"  value="0.6"/>
    <xacro:property name="height" value="0.2"/>
    <xacro:property name="depth"  value="1.0"/>
    <xacro:property name="red"    value="1.0 0.0 0.0 1.0"/>
    <xacro:property name="green"  value="0.0 1.0 0.0 1.0"/>
    <xacro:property name="blue"   value="0.0 0.0 1.0 1.0"/>
    <xacro:property name="yellow" value="1.0 1.0 0.0 1.0"/>

    <link name="base_link">
        <inertial>
            <origin xyz="0.0 0.0 0.0" rpy="0.0 0.0 0.0"/>
            <mass value="1.0"/>
            <inertia ixx="${constant*mass*(height*height+depth*depth)}" ixy="0.0" ixz="0.0" 
                     iyy="${constant*mass*(width*width+height*height)}" iyz="0.0" 
                     izz="${constant*mass*(width*width+depth*depth)}"/>
        </inertial>

        <visual name="">
            <origin xyz="0.0 0.0 0.0" rpy="0.0 0.0 0.0"/>
            <geometry>
                <box size="${depth} ${width} ${height}"/>
            </geometry>
            <material name="red">
                <color rgba="1.0 0.0 0.0 1.0"/>
                <texture filename=""/>
            </material>
        </visual>
   </link>

    <joint name="base_joint" type="fixed">
        <origin xyz="0.0 0.0 0.2" rpy="0.0 0.0 0.0"/>
        <parent link="base_footprint"/>
        <child link="base_link"/>
        <axis xyz="0.0 0.0 0.0"/>
    </joint>

    <xacro:macro name="wheel" params="color name x y mesh angle_wheel">
        <joint name="wheel_${name}_joint" type="continuous">
            <parent link="base_link"/>
            <child link="wheel_${name}_link"/>
            <origin xyz="${x} ${y} 0.0" rpy="0.0 0.0 ${angle_wheel}"/>
            <axis xyz="0.0 1.0 0.0"/>
        </joint>

        <link name="wheel_${name}_link">
            <inertial>
                <origin xyz="0.0 0.0 0.0" rpy="0.0 0.0 0.0"/>
                <mass value="0.5"/>
                <inertia ixx="0.0" ixy="0.0" ixz="0.0" iyy="0.0" iyz="0.0" izz="0.0"/>
            </inertial>
            
            <visual name="">
        <!--            <origin xyz="0.35 0.35 0.0" rpy="${pi/2} 0.0 ${pi/2}"/> -->
                <origin xyz="0.0 0.0 0.0" rpy="0.0 0.0 0.0"/>
                    <geometry>
                        <!-- <cylinder radius="0.15" length="0.1"/> -->
                        <mesh filename="package://mobile_robot/meshes/left_tire.stl" scale="0.005 0.005 0.005"/>
                    </geometry>
                    <material name="yellow">
                        <color rgba="${color}"/>
                        <texture filename=""/>
                    </material>
            </visual>
            <collision>
                <origin xyz="0.0 0.0 0.0" rpy="0.0 0.0 0.0"/>
                <geometry>
                        <!-- <cylinder radius="0.15" length="0.1"/> -->
                        <mesh filename="${mesh}" scale="0.005 0.005 0.005"/>
                </geometry>
            </collision>
        </link>
        
    </xacro:macro>

    <xacro:wheel color="${green}" name="front_right" x="0.35" y="-0.35" mesh="${right_wheel}" angle_wheel="0.0"/>
    <xacro:wheel color="${yellow}" name="front_left" x="0.35" y="0.35" mesh="${left_wheel}" angle_wheel="0.0"/>
    <xacro:wheel color="${blue}" name="rear_right" x="-0.35" y="-0.35" mesh="${right_wheel}" angle_wheel="0.0"/>
    <xacro:wheel color="${red}" name="rear_left" x="-0.35" y="0.35" mesh="${left_wheel}" angle_wheel="0.0"/>
    <xacro:include filename="$(find mobile_robot)/urdf/rover_gazebo.xacro"/>
</robot>
